2019-05-14 19:20:34,876 - INFO - app:is_valid - lineno:94 - username:265254,password:salvisa, kentucky, usa: has login success
2019-05-14 20:11:21,797 - INFO - app:is_valid - lineno:94 - username:265254,password:salvisa, kentucky, usa: has login success
2019-05-14 20:23:36,272 - ERROR - app:root - lineno:34 - select hot books error: 'NoneType' object has no attribute 'read'
Traceback (most recent call last):
  File "/home/adam/桌面/server/图书推荐系统/app.py", line 30, in root
    hot_books = mysql.fetchall_db(sql)
  File "/home/adam/桌面/server/图书推荐系统/utils.py", line 42, in fetchall_db
    c.execute(sql)
  File "/home/adam/anaconda3/envs/tensorflow-gpu/lib/python3.6/site-packages/pymysql/cursors.py", line 170, in execute
    result = self._query(query)
  File "/home/adam/anaconda3/envs/tensorflow-gpu/lib/python3.6/site-packages/pymysql/cursors.py", line 328, in _query
    conn.query(q)
  File "/home/adam/anaconda3/envs/tensorflow-gpu/lib/python3.6/site-packages/pymysql/connections.py", line 517, in query
    self._affected_rows = self._read_query_result(unbuffered=unbuffered)
  File "/home/adam/anaconda3/envs/tensorflow-gpu/lib/python3.6/site-packages/pymysql/connections.py", line 732, in _read_query_result
    result.read()
  File "/home/adam/anaconda3/envs/tensorflow-gpu/lib/python3.6/site-packages/pymysql/connections.py", line 1082, in read
    self._read_result_packet(first_packet)
  File "/home/adam/anaconda3/envs/tensorflow-gpu/lib/python3.6/site-packages/pymysql/connections.py", line 1151, in _read_result_packet
    self._get_descriptions()
  File "/home/adam/anaconda3/envs/tensorflow-gpu/lib/python3.6/site-packages/pymysql/connections.py", line 1222, in _get_descriptions
    field = self.connection._read_packet(FieldDescriptorPacket)
  File "/home/adam/anaconda3/envs/tensorflow-gpu/lib/python3.6/site-packages/pymysql/connections.py", line 674, in _read_packet
    recv_data = self._read_bytes(bytes_to_read)
  File "/home/adam/anaconda3/envs/tensorflow-gpu/lib/python3.6/site-packages/pymysql/connections.py", line 691, in _read_bytes
    data = self._rfile.read(num_bytes)
AttributeError: 'NoneType' object has no attribute 'read'
2019-05-14 20:23:36,272 - ERROR - app:root - lineno:34 - select hot books error: Packet sequence number wrong - got 102 expected 4
Traceback (most recent call last):
  File "/home/adam/桌面/server/图书推荐系统/app.py", line 30, in root
    hot_books = mysql.fetchall_db(sql)
  File "/home/adam/桌面/server/图书推荐系统/utils.py", line 42, in fetchall_db
    c.execute(sql)
  File "/home/adam/anaconda3/envs/tensorflow-gpu/lib/python3.6/site-packages/pymysql/cursors.py", line 170, in execute
    result = self._query(query)
  File "/home/adam/anaconda3/envs/tensorflow-gpu/lib/python3.6/site-packages/pymysql/cursors.py", line 328, in _query
    conn.query(q)
  File "/home/adam/anaconda3/envs/tensorflow-gpu/lib/python3.6/site-packages/pymysql/connections.py", line 517, in query
    self._affected_rows = self._read_query_result(unbuffered=unbuffered)
  File "/home/adam/anaconda3/envs/tensorflow-gpu/lib/python3.6/site-packages/pymysql/connections.py", line 732, in _read_query_result
    result.read()
  File "/home/adam/anaconda3/envs/tensorflow-gpu/lib/python3.6/site-packages/pymysql/connections.py", line 1075, in read
    first_packet = self.connection._read_packet()
  File "/home/adam/anaconda3/envs/tensorflow-gpu/lib/python3.6/site-packages/pymysql/connections.py", line 671, in _read_packet
    % (packet_number, self._next_seq_id))
pymysql.err.InternalError: Packet sequence number wrong - got 102 expected 4
2019-05-14 20:23:36,450 - ERROR - app:root - lineno:34 - select hot books error: (0, '')
Traceback (most recent call last):
  File "/home/adam/桌面/server/图书推荐系统/app.py", line 30, in root
    hot_books = mysql.fetchall_db(sql)
  File "/home/adam/桌面/server/图书推荐系统/utils.py", line 42, in fetchall_db
    c.execute(sql)
  File "/home/adam/anaconda3/envs/tensorflow-gpu/lib/python3.6/site-packages/pymysql/cursors.py", line 170, in execute
    result = self._query(query)
  File "/home/adam/anaconda3/envs/tensorflow-gpu/lib/python3.6/site-packages/pymysql/cursors.py", line 328, in _query
    conn.query(q)
  File "/home/adam/anaconda3/envs/tensorflow-gpu/lib/python3.6/site-packages/pymysql/connections.py", line 516, in query
    self._execute_command(COMMAND.COM_QUERY, sql)
  File "/home/adam/anaconda3/envs/tensorflow-gpu/lib/python3.6/site-packages/pymysql/connections.py", line 750, in _execute_command
    raise err.InterfaceError("(0, '')")
pymysql.err.InterfaceError: (0, '')
2019-05-14 20:23:36,635 - ERROR - app:root - lineno:34 - select hot books error: (0, '')
Traceback (most recent call last):
  File "/home/adam/桌面/server/图书推荐系统/app.py", line 30, in root
    hot_books = mysql.fetchall_db(sql)
  File "/home/adam/桌面/server/图书推荐系统/utils.py", line 42, in fetchall_db
    c.execute(sql)
  File "/home/adam/anaconda3/envs/tensorflow-gpu/lib/python3.6/site-packages/pymysql/cursors.py", line 170, in execute
    result = self._query(query)
  File "/home/adam/anaconda3/envs/tensorflow-gpu/lib/python3.6/site-packages/pymysql/cursors.py", line 328, in _query
    conn.query(q)
  File "/home/adam/anaconda3/envs/tensorflow-gpu/lib/python3.6/site-packages/pymysql/connections.py", line 516, in query
    self._execute_command(COMMAND.COM_QUERY, sql)
  File "/home/adam/anaconda3/envs/tensorflow-gpu/lib/python3.6/site-packages/pymysql/connections.py", line 750, in _execute_command
    raise err.InterfaceError("(0, '')")
pymysql.err.InterfaceError: (0, '')
2019-05-14 20:23:36,793 - ERROR - app:root - lineno:34 - select hot books error: (0, '')
Traceback (most recent call last):
  File "/home/adam/桌面/server/图书推荐系统/app.py", line 30, in root
    hot_books = mysql.fetchall_db(sql)
  File "/home/adam/桌面/server/图书推荐系统/utils.py", line 42, in fetchall_db
    c.execute(sql)
  File "/home/adam/anaconda3/envs/tensorflow-gpu/lib/python3.6/site-packages/pymysql/cursors.py", line 170, in execute
    result = self._query(query)
  File "/home/adam/anaconda3/envs/tensorflow-gpu/lib/python3.6/site-packages/pymysql/cursors.py", line 328, in _query
    conn.query(q)
  File "/home/adam/anaconda3/envs/tensorflow-gpu/lib/python3.6/site-packages/pymysql/connections.py", line 516, in query
    self._execute_command(COMMAND.COM_QUERY, sql)
  File "/home/adam/anaconda3/envs/tensorflow-gpu/lib/python3.6/site-packages/pymysql/connections.py", line 750, in _execute_command
    raise err.InterfaceError("(0, '')")
pymysql.err.InterfaceError: (0, '')
2019-05-14 20:23:39,284 - ERROR - app:root - lineno:34 - select hot books error: (0, '')
Traceback (most recent call last):
  File "/home/adam/桌面/server/图书推荐系统/app.py", line 30, in root
    hot_books = mysql.fetchall_db(sql)
  File "/home/adam/桌面/server/图书推荐系统/utils.py", line 42, in fetchall_db
    c.execute(sql)
  File "/home/adam/anaconda3/envs/tensorflow-gpu/lib/python3.6/site-packages/pymysql/cursors.py", line 170, in execute
    result = self._query(query)
  File "/home/adam/anaconda3/envs/tensorflow-gpu/lib/python3.6/site-packages/pymysql/cursors.py", line 328, in _query
    conn.query(q)
  File "/home/adam/anaconda3/envs/tensorflow-gpu/lib/python3.6/site-packages/pymysql/connections.py", line 516, in query
    self._execute_command(COMMAND.COM_QUERY, sql)
  File "/home/adam/anaconda3/envs/tensorflow-gpu/lib/python3.6/site-packages/pymysql/connections.py", line 750, in _execute_command
    raise err.InterfaceError("(0, '')")
pymysql.err.InterfaceError: (0, '')
2019-05-14 20:23:41,158 - ERROR - app:is_valid - lineno:100 - username:265254,password:salvisa, kentucky, usa: has login error
Traceback (most recent call last):
  File "/home/adam/桌面/server/图书推荐系统/app.py", line 91, in is_valid
    result = mysql.fetchone_db(sql)
  File "/home/adam/桌面/server/图书推荐系统/utils.py", line 32, in fetchone_db
    c.execute(sql)
  File "/home/adam/anaconda3/envs/tensorflow-gpu/lib/python3.6/site-packages/pymysql/cursors.py", line 170, in execute
    result = self._query(query)
  File "/home/adam/anaconda3/envs/tensorflow-gpu/lib/python3.6/site-packages/pymysql/cursors.py", line 328, in _query
    conn.query(q)
  File "/home/adam/anaconda3/envs/tensorflow-gpu/lib/python3.6/site-packages/pymysql/connections.py", line 516, in query
    self._execute_command(COMMAND.COM_QUERY, sql)
  File "/home/adam/anaconda3/envs/tensorflow-gpu/lib/python3.6/site-packages/pymysql/connections.py", line 750, in _execute_command
    raise err.InterfaceError("(0, '')")
pymysql.err.InterfaceError: (0, '')
2019-05-14 20:23:42,245 - ERROR - app:is_valid - lineno:100 - username:265254,password:salvisa, kentucky, usa: has login error
Traceback (most recent call last):
  File "/home/adam/桌面/server/图书推荐系统/app.py", line 91, in is_valid
    result = mysql.fetchone_db(sql)
  File "/home/adam/桌面/server/图书推荐系统/utils.py", line 32, in fetchone_db
    c.execute(sql)
  File "/home/adam/anaconda3/envs/tensorflow-gpu/lib/python3.6/site-packages/pymysql/cursors.py", line 170, in execute
    result = self._query(query)
  File "/home/adam/anaconda3/envs/tensorflow-gpu/lib/python3.6/site-packages/pymysql/cursors.py", line 328, in _query
    conn.query(q)
  File "/home/adam/anaconda3/envs/tensorflow-gpu/lib/python3.6/site-packages/pymysql/connections.py", line 516, in query
    self._execute_command(COMMAND.COM_QUERY, sql)
  File "/home/adam/anaconda3/envs/tensorflow-gpu/lib/python3.6/site-packages/pymysql/connections.py", line 750, in _execute_command
    raise err.InterfaceError("(0, '')")
pymysql.err.InterfaceError: (0, '')
2019-05-14 20:23:42,798 - ERROR - app:is_valid - lineno:100 - username:265254,password:salvisa, kentucky, usa: has login error
Traceback (most recent call last):
  File "/home/adam/桌面/server/图书推荐系统/app.py", line 91, in is_valid
    result = mysql.fetchone_db(sql)
  File "/home/adam/桌面/server/图书推荐系统/utils.py", line 32, in fetchone_db
    c.execute(sql)
  File "/home/adam/anaconda3/envs/tensorflow-gpu/lib/python3.6/site-packages/pymysql/cursors.py", line 170, in execute
    result = self._query(query)
  File "/home/adam/anaconda3/envs/tensorflow-gpu/lib/python3.6/site-packages/pymysql/cursors.py", line 328, in _query
    conn.query(q)
  File "/home/adam/anaconda3/envs/tensorflow-gpu/lib/python3.6/site-packages/pymysql/connections.py", line 516, in query
    self._execute_command(COMMAND.COM_QUERY, sql)
  File "/home/adam/anaconda3/envs/tensorflow-gpu/lib/python3.6/site-packages/pymysql/connections.py", line 750, in _execute_command
    raise err.InterfaceError("(0, '')")
pymysql.err.InterfaceError: (0, '')
2019-05-14 20:23:42,999 - ERROR - app:is_valid - lineno:100 - username:265254,password:salvisa, kentucky, usa: has login error
Traceback (most recent call last):
  File "/home/adam/桌面/server/图书推荐系统/app.py", line 91, in is_valid
    result = mysql.fetchone_db(sql)
  File "/home/adam/桌面/server/图书推荐系统/utils.py", line 32, in fetchone_db
    c.execute(sql)
  File "/home/adam/anaconda3/envs/tensorflow-gpu/lib/python3.6/site-packages/pymysql/cursors.py", line 170, in execute
    result = self._query(query)
  File "/home/adam/anaconda3/envs/tensorflow-gpu/lib/python3.6/site-packages/pymysql/cursors.py", line 328, in _query
    conn.query(q)
  File "/home/adam/anaconda3/envs/tensorflow-gpu/lib/python3.6/site-packages/pymysql/connections.py", line 516, in query
    self._execute_command(COMMAND.COM_QUERY, sql)
  File "/home/adam/anaconda3/envs/tensorflow-gpu/lib/python3.6/site-packages/pymysql/connections.py", line 750, in _execute_command
    raise err.InterfaceError("(0, '')")
pymysql.err.InterfaceError: (0, '')
2019-05-14 20:23:49,429 - INFO - app:is_valid - lineno:94 - username:265254,password:salvisa, kentucky, usa: has login success
2019-05-14 20:33:06,731 - ERROR - app:search - lineno:181 - select search books error: (1267, "Illegal mix of collations (latin1_swedish_ci,IMPLICIT) and (utf8_general_ci,COERCIBLE) for operation 'like'")
Traceback (most recent call last):
  File "/home/adam/桌面/server/图书推荐系统/app.py", line 178, in search
    search_books = mysql.fetchall_db(sql)
  File "/home/adam/桌面/server/图书推荐系统/utils.py", line 42, in fetchall_db
    c.execute(sql)
  File "/home/adam/anaconda3/envs/tensorflow-gpu/lib/python3.6/site-packages/pymysql/cursors.py", line 170, in execute
    result = self._query(query)
  File "/home/adam/anaconda3/envs/tensorflow-gpu/lib/python3.6/site-packages/pymysql/cursors.py", line 328, in _query
    conn.query(q)
  File "/home/adam/anaconda3/envs/tensorflow-gpu/lib/python3.6/site-packages/pymysql/connections.py", line 517, in query
    self._affected_rows = self._read_query_result(unbuffered=unbuffered)
  File "/home/adam/anaconda3/envs/tensorflow-gpu/lib/python3.6/site-packages/pymysql/connections.py", line 732, in _read_query_result
    result.read()
  File "/home/adam/anaconda3/envs/tensorflow-gpu/lib/python3.6/site-packages/pymysql/connections.py", line 1075, in read
    first_packet = self.connection._read_packet()
  File "/home/adam/anaconda3/envs/tensorflow-gpu/lib/python3.6/site-packages/pymysql/connections.py", line 684, in _read_packet
    packet.check_error()
  File "/home/adam/anaconda3/envs/tensorflow-gpu/lib/python3.6/site-packages/pymysql/protocol.py", line 220, in check_error
    err.raise_mysql_exception(self._data)
  File "/home/adam/anaconda3/envs/tensorflow-gpu/lib/python3.6/site-packages/pymysql/err.py", line 109, in raise_mysql_exception
    raise errorclass(errno, errval)
pymysql.err.InternalError: (1267, "Illegal mix of collations (latin1_swedish_ci,IMPLICIT) and (utf8_general_ci,COERCIBLE) for operation 'like'")
2019-05-14 20:33:14,448 - ERROR - app:search - lineno:181 - select search books error: name 'book_info' is not defined
Traceback (most recent call last):
  File "/home/adam/桌面/server/图书推荐系统/app.py", line 179, in search
    search_books = [v for k,v in book_info[0].items()]
NameError: name 'book_info' is not defined
2019-05-14 20:33:50,329 - ERROR - app:search - lineno:182 - select search books error: name 'book_info' is not defined
Traceback (most recent call last):
  File "/home/adam/桌面/server/图书推荐系统/app.py", line 179, in search
    search_books = [v for k,v in book_info[0].items()]
NameError: name 'book_info' is not defined
2019-05-14 20:33:52,427 - ERROR - app:search - lineno:182 - select search books error: name 'book_info' is not defined
Traceback (most recent call last):
  File "/home/adam/桌面/server/图书推荐系统/app.py", line 179, in search
    search_books = [v for k,v in book_info[0].items()]
NameError: name 'book_info' is not defined
2019-05-14 20:33:56,124 - ERROR - app:search - lineno:182 - select search books error: name 'book_info' is not defined
Traceback (most recent call last):
  File "/home/adam/桌面/server/图书推荐系统/app.py", line 179, in search
    search_books = [v for k,v in book_info[0].items()]
NameError: name 'book_info' is not defined
2019-05-14 20:34:08,030 - ERROR - app:search - lineno:182 - select search books error: name 'book_info' is not defined
Traceback (most recent call last):
  File "/home/adam/桌面/server/图书推荐系统/app.py", line 179, in search
    search_books = [v for k,v in book_info[0].items()]
NameError: name 'book_info' is not defined
2019-05-14 20:35:21,501 - ERROR - app:search - lineno:182 - select search books error: 'list' object has no attribute 'items'
Traceback (most recent call last):
  File "/home/adam/桌面/server/图书推荐系统/app.py", line 179, in search
    search_books = [v for k,v in search_books.items()]
AttributeError: 'list' object has no attribute 'items'
2019-05-14 20:35:27,612 - ERROR - app:search - lineno:182 - select search books error: 'list' object has no attribute 'items'
Traceback (most recent call last):
  File "/home/adam/桌面/server/图书推荐系统/app.py", line 179, in search
    search_books = [v for k,v in search_books.items()]
AttributeError: 'list' object has no attribute 'items'
2019-05-14 20:36:48,369 - ERROR - app:search - lineno:181 - select search books error: (1267, "Illegal mix of collations (latin1_swedish_ci,IMPLICIT) and (utf8_general_ci,COERCIBLE) for operation 'like'")
Traceback (most recent call last):
  File "/home/adam/桌面/server/图书推荐系统/app.py", line 178, in search
    search_books = mysql.fetchall_db(sql)
  File "/home/adam/桌面/server/图书推荐系统/utils.py", line 42, in fetchall_db
    c.execute(sql)
  File "/home/adam/anaconda3/envs/tensorflow-gpu/lib/python3.6/site-packages/pymysql/cursors.py", line 170, in execute
    result = self._query(query)
  File "/home/adam/anaconda3/envs/tensorflow-gpu/lib/python3.6/site-packages/pymysql/cursors.py", line 328, in _query
    conn.query(q)
  File "/home/adam/anaconda3/envs/tensorflow-gpu/lib/python3.6/site-packages/pymysql/connections.py", line 517, in query
    self._affected_rows = self._read_query_result(unbuffered=unbuffered)
  File "/home/adam/anaconda3/envs/tensorflow-gpu/lib/python3.6/site-packages/pymysql/connections.py", line 732, in _read_query_result
    result.read()
  File "/home/adam/anaconda3/envs/tensorflow-gpu/lib/python3.6/site-packages/pymysql/connections.py", line 1075, in read
    first_packet = self.connection._read_packet()
  File "/home/adam/anaconda3/envs/tensorflow-gpu/lib/python3.6/site-packages/pymysql/connections.py", line 684, in _read_packet
    packet.check_error()
  File "/home/adam/anaconda3/envs/tensorflow-gpu/lib/python3.6/site-packages/pymysql/protocol.py", line 220, in check_error
    err.raise_mysql_exception(self._data)
  File "/home/adam/anaconda3/envs/tensorflow-gpu/lib/python3.6/site-packages/pymysql/err.py", line 109, in raise_mysql_exception
    raise errorclass(errno, errval)
pymysql.err.InternalError: (1267, "Illegal mix of collations (latin1_swedish_ci,IMPLICIT) and (utf8_general_ci,COERCIBLE) for operation 'like'")
2019-05-14 20:39:36,830 - ERROR - app:search - lineno:181 - select search books error: (1267, "Illegal mix of collations (latin1_swedish_ci,IMPLICIT) and (utf8_general_ci,COERCIBLE) for operation 'like'")
Traceback (most recent call last):
  File "/home/adam/桌面/server/图书推荐系统/app.py", line 178, in search
    search_books = mysql.fetchall_db(sql)
  File "/home/adam/桌面/server/图书推荐系统/utils.py", line 42, in fetchall_db
    c.execute(sql)
  File "/home/adam/anaconda3/envs/tensorflow-gpu/lib/python3.6/site-packages/pymysql/cursors.py", line 170, in execute
    result = self._query(query)
  File "/home/adam/anaconda3/envs/tensorflow-gpu/lib/python3.6/site-packages/pymysql/cursors.py", line 328, in _query
    conn.query(q)
  File "/home/adam/anaconda3/envs/tensorflow-gpu/lib/python3.6/site-packages/pymysql/connections.py", line 517, in query
    self._affected_rows = self._read_query_result(unbuffered=unbuffered)
  File "/home/adam/anaconda3/envs/tensorflow-gpu/lib/python3.6/site-packages/pymysql/connections.py", line 732, in _read_query_result
    result.read()
  File "/home/adam/anaconda3/envs/tensorflow-gpu/lib/python3.6/site-packages/pymysql/connections.py", line 1075, in read
    first_packet = self.connection._read_packet()
  File "/home/adam/anaconda3/envs/tensorflow-gpu/lib/python3.6/site-packages/pymysql/connections.py", line 684, in _read_packet
    packet.check_error()
  File "/home/adam/anaconda3/envs/tensorflow-gpu/lib/python3.6/site-packages/pymysql/protocol.py", line 220, in check_error
    err.raise_mysql_exception(self._data)
  File "/home/adam/anaconda3/envs/tensorflow-gpu/lib/python3.6/site-packages/pymysql/err.py", line 109, in raise_mysql_exception
    raise errorclass(errno, errval)
pymysql.err.InternalError: (1267, "Illegal mix of collations (latin1_swedish_ci,IMPLICIT) and (utf8_general_ci,COERCIBLE) for operation 'like'")
2019-05-14 20:40:05,993 - ERROR - app:search - lineno:181 - select search books error: (1267, "Illegal mix of collations (latin1_swedish_ci,IMPLICIT) and (utf8_general_ci,COERCIBLE) for operation 'like'")
Traceback (most recent call last):
  File "/home/adam/桌面/server/图书推荐系统/app.py", line 178, in search
    search_books = mysql.fetchall_db(sql)
  File "/home/adam/桌面/server/图书推荐系统/utils.py", line 42, in fetchall_db
    c.execute(sql)
  File "/home/adam/anaconda3/envs/tensorflow-gpu/lib/python3.6/site-packages/pymysql/cursors.py", line 170, in execute
    result = self._query(query)
  File "/home/adam/anaconda3/envs/tensorflow-gpu/lib/python3.6/site-packages/pymysql/cursors.py", line 328, in _query
    conn.query(q)
  File "/home/adam/anaconda3/envs/tensorflow-gpu/lib/python3.6/site-packages/pymysql/connections.py", line 517, in query
    self._affected_rows = self._read_query_result(unbuffered=unbuffered)
  File "/home/adam/anaconda3/envs/tensorflow-gpu/lib/python3.6/site-packages/pymysql/connections.py", line 732, in _read_query_result
    result.read()
  File "/home/adam/anaconda3/envs/tensorflow-gpu/lib/python3.6/site-packages/pymysql/connections.py", line 1075, in read
    first_packet = self.connection._read_packet()
  File "/home/adam/anaconda3/envs/tensorflow-gpu/lib/python3.6/site-packages/pymysql/connections.py", line 684, in _read_packet
    packet.check_error()
  File "/home/adam/anaconda3/envs/tensorflow-gpu/lib/python3.6/site-packages/pymysql/protocol.py", line 220, in check_error
    err.raise_mysql_exception(self._data)
  File "/home/adam/anaconda3/envs/tensorflow-gpu/lib/python3.6/site-packages/pymysql/err.py", line 109, in raise_mysql_exception
    raise errorclass(errno, errval)
pymysql.err.InternalError: (1267, "Illegal mix of collations (latin1_swedish_ci,IMPLICIT) and (utf8_general_ci,COERCIBLE) for operation 'like'")
2019-05-14 20:43:21,612 - ERROR - app:search - lineno:181 - select search books error: (1267, "Illegal mix of collations (latin1_swedish_ci,IMPLICIT) and (utf8_general_ci,COERCIBLE) for operation 'like'")
Traceback (most recent call last):
  File "/home/adam/桌面/server/图书推荐系统/app.py", line 178, in search
    search_books = mysql.fetchall_db(sql)
  File "/home/adam/桌面/server/图书推荐系统/utils.py", line 42, in fetchall_db
    c.execute(sql)
  File "/home/adam/anaconda3/envs/tensorflow-gpu/lib/python3.6/site-packages/pymysql/cursors.py", line 170, in execute
    result = self._query(query)
  File "/home/adam/anaconda3/envs/tensorflow-gpu/lib/python3.6/site-packages/pymysql/cursors.py", line 328, in _query
    conn.query(q)
  File "/home/adam/anaconda3/envs/tensorflow-gpu/lib/python3.6/site-packages/pymysql/connections.py", line 517, in query
    self._affected_rows = self._read_query_result(unbuffered=unbuffered)
  File "/home/adam/anaconda3/envs/tensorflow-gpu/lib/python3.6/site-packages/pymysql/connections.py", line 732, in _read_query_result
    result.read()
  File "/home/adam/anaconda3/envs/tensorflow-gpu/lib/python3.6/site-packages/pymysql/connections.py", line 1075, in read
    first_packet = self.connection._read_packet()
  File "/home/adam/anaconda3/envs/tensorflow-gpu/lib/python3.6/site-packages/pymysql/connections.py", line 684, in _read_packet
    packet.check_error()
  File "/home/adam/anaconda3/envs/tensorflow-gpu/lib/python3.6/site-packages/pymysql/protocol.py", line 220, in check_error
    err.raise_mysql_exception(self._data)
  File "/home/adam/anaconda3/envs/tensorflow-gpu/lib/python3.6/site-packages/pymysql/err.py", line 109, in raise_mysql_exception
    raise errorclass(errno, errval)
pymysql.err.InternalError: (1267, "Illegal mix of collations (latin1_swedish_ci,IMPLICIT) and (utf8_general_ci,COERCIBLE) for operation 'like'")
2019-05-14 20:43:24,592 - ERROR - app:search - lineno:181 - select search books error: (1267, "Illegal mix of collations (latin1_swedish_ci,IMPLICIT) and (utf8_general_ci,COERCIBLE) for operation 'like'")
Traceback (most recent call last):
  File "/home/adam/桌面/server/图书推荐系统/app.py", line 178, in search
    search_books = mysql.fetchall_db(sql)
  File "/home/adam/桌面/server/图书推荐系统/utils.py", line 42, in fetchall_db
    c.execute(sql)
  File "/home/adam/anaconda3/envs/tensorflow-gpu/lib/python3.6/site-packages/pymysql/cursors.py", line 170, in execute
    result = self._query(query)
  File "/home/adam/anaconda3/envs/tensorflow-gpu/lib/python3.6/site-packages/pymysql/cursors.py", line 328, in _query
    conn.query(q)
  File "/home/adam/anaconda3/envs/tensorflow-gpu/lib/python3.6/site-packages/pymysql/connections.py", line 517, in query
    self._affected_rows = self._read_query_result(unbuffered=unbuffered)
  File "/home/adam/anaconda3/envs/tensorflow-gpu/lib/python3.6/site-packages/pymysql/connections.py", line 732, in _read_query_result
    result.read()
  File "/home/adam/anaconda3/envs/tensorflow-gpu/lib/python3.6/site-packages/pymysql/connections.py", line 1075, in read
    first_packet = self.connection._read_packet()
  File "/home/adam/anaconda3/envs/tensorflow-gpu/lib/python3.6/site-packages/pymysql/connections.py", line 684, in _read_packet
    packet.check_error()
  File "/home/adam/anaconda3/envs/tensorflow-gpu/lib/python3.6/site-packages/pymysql/protocol.py", line 220, in check_error
    err.raise_mysql_exception(self._data)
  File "/home/adam/anaconda3/envs/tensorflow-gpu/lib/python3.6/site-packages/pymysql/err.py", line 109, in raise_mysql_exception
    raise errorclass(errno, errval)
pymysql.err.InternalError: (1267, "Illegal mix of collations (latin1_swedish_ci,IMPLICIT) and (utf8_general_ci,COERCIBLE) for operation 'like'")
2019-05-14 20:43:25,530 - ERROR - app:search - lineno:181 - select search books error: (1267, "Illegal mix of collations (latin1_swedish_ci,IMPLICIT) and (utf8_general_ci,COERCIBLE) for operation 'like'")
Traceback (most recent call last):
  File "/home/adam/桌面/server/图书推荐系统/app.py", line 178, in search
    search_books = mysql.fetchall_db(sql)
  File "/home/adam/桌面/server/图书推荐系统/utils.py", line 42, in fetchall_db
    c.execute(sql)
  File "/home/adam/anaconda3/envs/tensorflow-gpu/lib/python3.6/site-packages/pymysql/cursors.py", line 170, in execute
    result = self._query(query)
  File "/home/adam/anaconda3/envs/tensorflow-gpu/lib/python3.6/site-packages/pymysql/cursors.py", line 328, in _query
    conn.query(q)
  File "/home/adam/anaconda3/envs/tensorflow-gpu/lib/python3.6/site-packages/pymysql/connections.py", line 517, in query
    self._affected_rows = self._read_query_result(unbuffered=unbuffered)
  File "/home/adam/anaconda3/envs/tensorflow-gpu/lib/python3.6/site-packages/pymysql/connections.py", line 732, in _read_query_result
    result.read()
  File "/home/adam/anaconda3/envs/tensorflow-gpu/lib/python3.6/site-packages/pymysql/connections.py", line 1075, in read
    first_packet = self.connection._read_packet()
  File "/home/adam/anaconda3/envs/tensorflow-gpu/lib/python3.6/site-packages/pymysql/connections.py", line 684, in _read_packet
    packet.check_error()
  File "/home/adam/anaconda3/envs/tensorflow-gpu/lib/python3.6/site-packages/pymysql/protocol.py", line 220, in check_error
    err.raise_mysql_exception(self._data)
  File "/home/adam/anaconda3/envs/tensorflow-gpu/lib/python3.6/site-packages/pymysql/err.py", line 109, in raise_mysql_exception
    raise errorclass(errno, errval)
pymysql.err.InternalError: (1267, "Illegal mix of collations (latin1_swedish_ci,IMPLICIT) and (utf8_general_ci,COERCIBLE) for operation 'like'")
2019-05-14 20:43:26,307 - ERROR - app:search - lineno:181 - select search books error: (1267, "Illegal mix of collations (latin1_swedish_ci,IMPLICIT) and (utf8_general_ci,COERCIBLE) for operation 'like'")
Traceback (most recent call last):
  File "/home/adam/桌面/server/图书推荐系统/app.py", line 178, in search
    search_books = mysql.fetchall_db(sql)
  File "/home/adam/桌面/server/图书推荐系统/utils.py", line 42, in fetchall_db
    c.execute(sql)
  File "/home/adam/anaconda3/envs/tensorflow-gpu/lib/python3.6/site-packages/pymysql/cursors.py", line 170, in execute
    result = self._query(query)
  File "/home/adam/anaconda3/envs/tensorflow-gpu/lib/python3.6/site-packages/pymysql/cursors.py", line 328, in _query
    conn.query(q)
  File "/home/adam/anaconda3/envs/tensorflow-gpu/lib/python3.6/site-packages/pymysql/connections.py", line 517, in query
    self._affected_rows = self._read_query_result(unbuffered=unbuffered)
  File "/home/adam/anaconda3/envs/tensorflow-gpu/lib/python3.6/site-packages/pymysql/connections.py", line 732, in _read_query_result
    result.read()
  File "/home/adam/anaconda3/envs/tensorflow-gpu/lib/python3.6/site-packages/pymysql/connections.py", line 1075, in read
    first_packet = self.connection._read_packet()
  File "/home/adam/anaconda3/envs/tensorflow-gpu/lib/python3.6/site-packages/pymysql/connections.py", line 684, in _read_packet
    packet.check_error()
  File "/home/adam/anaconda3/envs/tensorflow-gpu/lib/python3.6/site-packages/pymysql/protocol.py", line 220, in check_error
    err.raise_mysql_exception(self._data)
  File "/home/adam/anaconda3/envs/tensorflow-gpu/lib/python3.6/site-packages/pymysql/err.py", line 109, in raise_mysql_exception
    raise errorclass(errno, errval)
pymysql.err.InternalError: (1267, "Illegal mix of collations (latin1_swedish_ci,IMPLICIT) and (utf8_general_ci,COERCIBLE) for operation 'like'")
2019-05-14 20:43:29,377 - ERROR - app:search - lineno:181 - select search books error: (1267, "Illegal mix of collations (latin1_swedish_ci,IMPLICIT) and (utf8_general_ci,COERCIBLE) for operation 'like'")
Traceback (most recent call last):
  File "/home/adam/桌面/server/图书推荐系统/app.py", line 178, in search
    search_books = mysql.fetchall_db(sql)
  File "/home/adam/桌面/server/图书推荐系统/utils.py", line 42, in fetchall_db
    c.execute(sql)
  File "/home/adam/anaconda3/envs/tensorflow-gpu/lib/python3.6/site-packages/pymysql/cursors.py", line 170, in execute
    result = self._query(query)
  File "/home/adam/anaconda3/envs/tensorflow-gpu/lib/python3.6/site-packages/pymysql/cursors.py", line 328, in _query
    conn.query(q)
  File "/home/adam/anaconda3/envs/tensorflow-gpu/lib/python3.6/site-packages/pymysql/connections.py", line 517, in query
    self._affected_rows = self._read_query_result(unbuffered=unbuffered)
  File "/home/adam/anaconda3/envs/tensorflow-gpu/lib/python3.6/site-packages/pymysql/connections.py", line 732, in _read_query_result
    result.read()
  File "/home/adam/anaconda3/envs/tensorflow-gpu/lib/python3.6/site-packages/pymysql/connections.py", line 1075, in read
    first_packet = self.connection._read_packet()
  File "/home/adam/anaconda3/envs/tensorflow-gpu/lib/python3.6/site-packages/pymysql/connections.py", line 684, in _read_packet
    packet.check_error()
  File "/home/adam/anaconda3/envs/tensorflow-gpu/lib/python3.6/site-packages/pymysql/protocol.py", line 220, in check_error
    err.raise_mysql_exception(self._data)
  File "/home/adam/anaconda3/envs/tensorflow-gpu/lib/python3.6/site-packages/pymysql/err.py", line 109, in raise_mysql_exception
    raise errorclass(errno, errval)
pymysql.err.InternalError: (1267, "Illegal mix of collations (latin1_swedish_ci,IMPLICIT) and (utf8_general_ci,COERCIBLE) for operation 'like'")
2019-05-14 20:43:29,873 - ERROR - app:search - lineno:181 - select search books error: (1267, "Illegal mix of collations (latin1_swedish_ci,IMPLICIT) and (utf8_general_ci,COERCIBLE) for operation 'like'")
Traceback (most recent call last):
  File "/home/adam/桌面/server/图书推荐系统/app.py", line 178, in search
    search_books = mysql.fetchall_db(sql)
  File "/home/adam/桌面/server/图书推荐系统/utils.py", line 42, in fetchall_db
    c.execute(sql)
  File "/home/adam/anaconda3/envs/tensorflow-gpu/lib/python3.6/site-packages/pymysql/cursors.py", line 170, in execute
    result = self._query(query)
  File "/home/adam/anaconda3/envs/tensorflow-gpu/lib/python3.6/site-packages/pymysql/cursors.py", line 328, in _query
    conn.query(q)
  File "/home/adam/anaconda3/envs/tensorflow-gpu/lib/python3.6/site-packages/pymysql/connections.py", line 517, in query
    self._affected_rows = self._read_query_result(unbuffered=unbuffered)
  File "/home/adam/anaconda3/envs/tensorflow-gpu/lib/python3.6/site-packages/pymysql/connections.py", line 732, in _read_query_result
    result.read()
  File "/home/adam/anaconda3/envs/tensorflow-gpu/lib/python3.6/site-packages/pymysql/connections.py", line 1075, in read
    first_packet = self.connection._read_packet()
  File "/home/adam/anaconda3/envs/tensorflow-gpu/lib/python3.6/site-packages/pymysql/connections.py", line 684, in _read_packet
    packet.check_error()
  File "/home/adam/anaconda3/envs/tensorflow-gpu/lib/python3.6/site-packages/pymysql/protocol.py", line 220, in check_error
    err.raise_mysql_exception(self._data)
  File "/home/adam/anaconda3/envs/tensorflow-gpu/lib/python3.6/site-packages/pymysql/err.py", line 109, in raise_mysql_exception
    raise errorclass(errno, errval)
pymysql.err.InternalError: (1267, "Illegal mix of collations (latin1_swedish_ci,IMPLICIT) and (utf8_general_ci,COERCIBLE) for operation 'like'")
2019-05-14 20:43:30,082 - ERROR - app:search - lineno:181 - select search books error: (1267, "Illegal mix of collations (latin1_swedish_ci,IMPLICIT) and (utf8_general_ci,COERCIBLE) for operation 'like'")
Traceback (most recent call last):
  File "/home/adam/桌面/server/图书推荐系统/app.py", line 178, in search
    search_books = mysql.fetchall_db(sql)
  File "/home/adam/桌面/server/图书推荐系统/utils.py", line 42, in fetchall_db
    c.execute(sql)
  File "/home/adam/anaconda3/envs/tensorflow-gpu/lib/python3.6/site-packages/pymysql/cursors.py", line 170, in execute
    result = self._query(query)
  File "/home/adam/anaconda3/envs/tensorflow-gpu/lib/python3.6/site-packages/pymysql/cursors.py", line 328, in _query
    conn.query(q)
  File "/home/adam/anaconda3/envs/tensorflow-gpu/lib/python3.6/site-packages/pymysql/connections.py", line 517, in query
    self._affected_rows = self._read_query_result(unbuffered=unbuffered)
  File "/home/adam/anaconda3/envs/tensorflow-gpu/lib/python3.6/site-packages/pymysql/connections.py", line 732, in _read_query_result
    result.read()
  File "/home/adam/anaconda3/envs/tensorflow-gpu/lib/python3.6/site-packages/pymysql/connections.py", line 1075, in read
    first_packet = self.connection._read_packet()
  File "/home/adam/anaconda3/envs/tensorflow-gpu/lib/python3.6/site-packages/pymysql/connections.py", line 684, in _read_packet
    packet.check_error()
  File "/home/adam/anaconda3/envs/tensorflow-gpu/lib/python3.6/site-packages/pymysql/protocol.py", line 220, in check_error
    err.raise_mysql_exception(self._data)
  File "/home/adam/anaconda3/envs/tensorflow-gpu/lib/python3.6/site-packages/pymysql/err.py", line 109, in raise_mysql_exception
    raise errorclass(errno, errval)
pymysql.err.InternalError: (1267, "Illegal mix of collations (latin1_swedish_ci,IMPLICIT) and (utf8_general_ci,COERCIBLE) for operation 'like'")
2019-05-14 20:43:30,250 - ERROR - app:search - lineno:181 - select search books error: (1267, "Illegal mix of collations (latin1_swedish_ci,IMPLICIT) and (utf8_general_ci,COERCIBLE) for operation 'like'")
Traceback (most recent call last):
  File "/home/adam/桌面/server/图书推荐系统/app.py", line 178, in search
    search_books = mysql.fetchall_db(sql)
  File "/home/adam/桌面/server/图书推荐系统/utils.py", line 42, in fetchall_db
    c.execute(sql)
  File "/home/adam/anaconda3/envs/tensorflow-gpu/lib/python3.6/site-packages/pymysql/cursors.py", line 170, in execute
    result = self._query(query)
  File "/home/adam/anaconda3/envs/tensorflow-gpu/lib/python3.6/site-packages/pymysql/cursors.py", line 328, in _query
    conn.query(q)
  File "/home/adam/anaconda3/envs/tensorflow-gpu/lib/python3.6/site-packages/pymysql/connections.py", line 517, in query
    self._affected_rows = self._read_query_result(unbuffered=unbuffered)
  File "/home/adam/anaconda3/envs/tensorflow-gpu/lib/python3.6/site-packages/pymysql/connections.py", line 732, in _read_query_result
    result.read()
  File "/home/adam/anaconda3/envs/tensorflow-gpu/lib/python3.6/site-packages/pymysql/connections.py", line 1075, in read
    first_packet = self.connection._read_packet()
  File "/home/adam/anaconda3/envs/tensorflow-gpu/lib/python3.6/site-packages/pymysql/connections.py", line 684, in _read_packet
    packet.check_error()
  File "/home/adam/anaconda3/envs/tensorflow-gpu/lib/python3.6/site-packages/pymysql/protocol.py", line 220, in check_error
    err.raise_mysql_exception(self._data)
  File "/home/adam/anaconda3/envs/tensorflow-gpu/lib/python3.6/site-packages/pymysql/err.py", line 109, in raise_mysql_exception
    raise errorclass(errno, errval)
pymysql.err.InternalError: (1267, "Illegal mix of collations (latin1_swedish_ci,IMPLICIT) and (utf8_general_ci,COERCIBLE) for operation 'like'")
2019-05-14 20:43:37,082 - ERROR - app:search - lineno:181 - select search books error: (1267, "Illegal mix of collations (latin1_swedish_ci,IMPLICIT) and (utf8_general_ci,COERCIBLE) for operation 'like'")
Traceback (most recent call last):
  File "/home/adam/桌面/server/图书推荐系统/app.py", line 178, in search
    search_books = mysql.fetchall_db(sql)
  File "/home/adam/桌面/server/图书推荐系统/utils.py", line 42, in fetchall_db
    c.execute(sql)
  File "/home/adam/anaconda3/envs/tensorflow-gpu/lib/python3.6/site-packages/pymysql/cursors.py", line 170, in execute
    result = self._query(query)
  File "/home/adam/anaconda3/envs/tensorflow-gpu/lib/python3.6/site-packages/pymysql/cursors.py", line 328, in _query
    conn.query(q)
  File "/home/adam/anaconda3/envs/tensorflow-gpu/lib/python3.6/site-packages/pymysql/connections.py", line 517, in query
    self._affected_rows = self._read_query_result(unbuffered=unbuffered)
  File "/home/adam/anaconda3/envs/tensorflow-gpu/lib/python3.6/site-packages/pymysql/connections.py", line 732, in _read_query_result
    result.read()
  File "/home/adam/anaconda3/envs/tensorflow-gpu/lib/python3.6/site-packages/pymysql/connections.py", line 1075, in read
    first_packet = self.connection._read_packet()
  File "/home/adam/anaconda3/envs/tensorflow-gpu/lib/python3.6/site-packages/pymysql/connections.py", line 684, in _read_packet
    packet.check_error()
  File "/home/adam/anaconda3/envs/tensorflow-gpu/lib/python3.6/site-packages/pymysql/protocol.py", line 220, in check_error
    err.raise_mysql_exception(self._data)
  File "/home/adam/anaconda3/envs/tensorflow-gpu/lib/python3.6/site-packages/pymysql/err.py", line 109, in raise_mysql_exception
    raise errorclass(errno, errval)
pymysql.err.InternalError: (1267, "Illegal mix of collations (latin1_swedish_ci,IMPLICIT) and (utf8_general_ci,COERCIBLE) for operation 'like'")
2019-05-14 20:43:54,058 - ERROR - app:search - lineno:181 - select search books error: (1267, "Illegal mix of collations (latin1_swedish_ci,IMPLICIT) and (utf8_general_ci,COERCIBLE) for operation 'like'")
Traceback (most recent call last):
  File "/home/adam/桌面/server/图书推荐系统/app.py", line 178, in search
    search_books = mysql.fetchall_db(sql)
  File "/home/adam/桌面/server/图书推荐系统/utils.py", line 42, in fetchall_db
    c.execute(sql)
  File "/home/adam/anaconda3/envs/tensorflow-gpu/lib/python3.6/site-packages/pymysql/cursors.py", line 170, in execute
    result = self._query(query)
  File "/home/adam/anaconda3/envs/tensorflow-gpu/lib/python3.6/site-packages/pymysql/cursors.py", line 328, in _query
    conn.query(q)
  File "/home/adam/anaconda3/envs/tensorflow-gpu/lib/python3.6/site-packages/pymysql/connections.py", line 517, in query
    self._affected_rows = self._read_query_result(unbuffered=unbuffered)
  File "/home/adam/anaconda3/envs/tensorflow-gpu/lib/python3.6/site-packages/pymysql/connections.py", line 732, in _read_query_result
    result.read()
  File "/home/adam/anaconda3/envs/tensorflow-gpu/lib/python3.6/site-packages/pymysql/connections.py", line 1075, in read
    first_packet = self.connection._read_packet()
  File "/home/adam/anaconda3/envs/tensorflow-gpu/lib/python3.6/site-packages/pymysql/connections.py", line 684, in _read_packet
    packet.check_error()
  File "/home/adam/anaconda3/envs/tensorflow-gpu/lib/python3.6/site-packages/pymysql/protocol.py", line 220, in check_error
    err.raise_mysql_exception(self._data)
  File "/home/adam/anaconda3/envs/tensorflow-gpu/lib/python3.6/site-packages/pymysql/err.py", line 109, in raise_mysql_exception
    raise errorclass(errno, errval)
pymysql.err.InternalError: (1267, "Illegal mix of collations (latin1_swedish_ci,IMPLICIT) and (utf8_general_ci,COERCIBLE) for operation 'like'")
2019-05-14 20:44:03,117 - ERROR - app:search - lineno:181 - select search books error: (1267, "Illegal mix of collations (latin1_swedish_ci,IMPLICIT) and (utf8_general_ci,COERCIBLE) for operation 'like'")
Traceback (most recent call last):
  File "/home/adam/桌面/server/图书推荐系统/app.py", line 178, in search
    search_books = mysql.fetchall_db(sql)
  File "/home/adam/桌面/server/图书推荐系统/utils.py", line 42, in fetchall_db
    c.execute(sql)
  File "/home/adam/anaconda3/envs/tensorflow-gpu/lib/python3.6/site-packages/pymysql/cursors.py", line 170, in execute
    result = self._query(query)
  File "/home/adam/anaconda3/envs/tensorflow-gpu/lib/python3.6/site-packages/pymysql/cursors.py", line 328, in _query
    conn.query(q)
  File "/home/adam/anaconda3/envs/tensorflow-gpu/lib/python3.6/site-packages/pymysql/connections.py", line 517, in query
    self._affected_rows = self._read_query_result(unbuffered=unbuffered)
  File "/home/adam/anaconda3/envs/tensorflow-gpu/lib/python3.6/site-packages/pymysql/connections.py", line 732, in _read_query_result
    result.read()
  File "/home/adam/anaconda3/envs/tensorflow-gpu/lib/python3.6/site-packages/pymysql/connections.py", line 1075, in read
    first_packet = self.connection._read_packet()
  File "/home/adam/anaconda3/envs/tensorflow-gpu/lib/python3.6/site-packages/pymysql/connections.py", line 684, in _read_packet
    packet.check_error()
  File "/home/adam/anaconda3/envs/tensorflow-gpu/lib/python3.6/site-packages/pymysql/protocol.py", line 220, in check_error
    err.raise_mysql_exception(self._data)
  File "/home/adam/anaconda3/envs/tensorflow-gpu/lib/python3.6/site-packages/pymysql/err.py", line 109, in raise_mysql_exception
    raise errorclass(errno, errval)
pymysql.err.InternalError: (1267, "Illegal mix of collations (latin1_swedish_ci,IMPLICIT) and (utf8_general_ci,COERCIBLE) for operation 'like'")
